<?xml version='1.0'?>

<robot name="udacity_bot" xmlns:xacro="http://www.ros.org/wiki/xacro">
  <xacro:include filename="$(find slam_project)/urdf/udacity_bot.gazebo" />
  <link name="robot_footprint"></link>

  <joint name="robot_footprint_joint" type="fixed">
    <origin xyz="0 0 0" rpy="0 0 0" />
    <parent link="robot_footprint"/>
    <child link="chassis" />
  </joint>

  <link name='chassis'>
    <pose>0 0 0.1 0 0 0</pose>
    <inertial>
      <mass value="15.0"/>
      <origin xyz="0.0 0 0" rpy=" 0 0 0"/>
      <inertia
          ixx="0.1" ixy="0" ixz="0"
          iyy="0.1" iyz="0"
          izz="0.1" />
    </inertial>
    <collision name='collision'>
      <origin xyz="0 0 0" rpy=" 0 0 0"/> 
      <geometry>
        <box size=".4 .2 .1"/>
      </geometry>
    </collision>
    <visual name='chassis_visual'>
      <origin xyz="0 0 0" rpy=" 0 0 0"/>
      <geometry>
        <box size=".4 .2 .1"/>
      </geometry>
      <material name="cyan">
            <color rgba="0 1.0 1.0 1.0" />
      </material>
    </visual>
    <collision name='back_caster_collision'>
      <origin xyz="-0.15 0 -0.05" rpy=" 0 0 0"/>
      <geometry>
        <sphere radius="0.0499"/>
      </geometry>
      <surface>
        <friction>
          <ode>
            <mu>0</mu>
            <mu2>0</mu2>
            <slip1>1.0</slip1>
            <slip2>1.0</slip2>
          </ode>
        </friction>
      </surface>
    </collision>
    <visual name='back_caster_visual'>
      <origin xyz="-0.15 0 -0.05" rpy=" 0 0 0"/>
      <geometry>
        <sphere radius="0.0499"/>
      </geometry>
      <material name="cyan">
            <color rgba="0 1.0 1.0 1.0" />
      </material>
    </visual>
    <collision name='front_caster_collision'>
      <origin xyz="0.15 0 -0.05" rpy=" 0 0 0"/>
      <geometry>
        <sphere radius="0.0499"/>
      </geometry>
      <surface>
        <friction>
          <ode>
            <mu>0</mu>
            <mu2>0</mu2>
            <slip1>1.0</slip1>
            <slip2>1.0</slip2>
          </ode>
        </friction>
      </surface>
    </collision>
    <visual name='front_caster_visual'>
      <origin xyz="0.15 0 -0.05" rpy=" 0 0 0"/>
      <geometry>
        <sphere radius="0.0499"/>
      </geometry>
      <material name="cyan">
            <color rgba="0 1.0 1.0 1.0" />
      </material>
    </visual>
  </link>

  <link name='left_wheel'>
    <inertial>
      <mass value="5.0"/>
      <origin xyz="0.0 0 0" rpy=" 0 1.5707 1.5707"/>
      <inertia
          ixx="0.1" ixy="0" ixz="0"
          iyy="0.1" iyz="0"
          izz="0.1" />
    </inertial>
    <collision name='collision'>
      <origin xyz="0 0 0" rpy=" 0 1.5707 1.5707"/>
      <geometry>
        <cylinder radius=".1" length="0.05"/>
      </geometry>
    </collision>
    <visual name='left_wheel_visual'>
      <origin xyz="0 0 0" rpy=" 0 1.5707 1.5707"/>
      <geometry>
        <cylinder radius=".1" length="0.05"/>
      </geometry>
      <material name="green">
            <color rgba="0 1.0 0 1.0" />
      </material>
    </visual>
  </link>

  <joint type="continuous" name="left_wheel_hinge">
    <origin xyz="0 0.15 0" rpy="0 0 0"/>
    <child link="left_wheel"/>
    <parent link="chassis"/>
    <axis xyz="0 1 0" rpy="0 0 0"/>
    <limit effort="10000" velocity="1000"/>
    <joint_properties damping="1.0" friction="1.0"/>
  </joint>

  <link name='right_wheel'>
    <inertial>
      <mass value="5.0"/>
      <origin xyz="0.0 0 0" rpy=" 0 1.5707 1.5707"/>
      <inertia
          ixx="0.1" ixy="0" ixz="0"
          iyy="0.1" iyz="0"
          izz="0.1" />
    </inertial>
    <collision name='collision'>
      <origin xyz="0 0 0" rpy=" 0 1.5707 1.5707"/>
      <geometry>
        <cylinder radius=".1" length="0.05"/>
      </geometry>
    </collision>
    <visual>
      <origin xyz="0 0 0" rpy=" 0 1.5707 1.5707"/>
      <geometry>
        <cylinder radius=".1" length="0.05"/>
      </geometry>
      <material name="green">
            <color rgba="0 1.0 0 1.0" />
      </material>
    </visual>
  </link>

  <joint type="continuous" name="right_wheel_hinge">
    <origin xyz="0 -0.15 0" rpy="0 0 0"/>
    <child link="right_wheel"/>
    <parent link="chassis"/>
    <axis xyz="0 1 0" rpy="0 0 0"/>
    <limit effort="10000" velocity="1000"/>
    <joint_properties damping="1.0" friction="1.0"/>
  </joint>

  <link name='camera'>
    <inertial>
      <mass value="0.1"/>
      <origin xyz="0.0 0 0" rpy="0 0 0"/>
      <inertia
          ixx="1e-6" ixy="0" ixz="0"
          iyy="1e-6" iyz="0"
          izz="1e-6" />
    </inertial>
    <collision name='collision'>
      <origin xyz="0 0 0" rpy=" 0 0 0"/>
      <geometry>
        <box size="0.05 0.05 0.05"/>
      </geometry>
    </collision>
    <visual>
      <origin xyz="0 0 0" rpy="0 0 0"/>
      <geometry>
        <box size=".05 0.05 0.05"/>
      </geometry>
      <material name="red">
            <color rgba="1.0 0 0 1.0" />
      </material>
    </visual>
  </link>

  <joint type="fixed" name="camera_joint">
    <origin xyz="0.2 0 0.05" rpy="0 0 0"/>   
    <child link="camera"/>
    <parent link="chassis"/>
  </joint>

  <link name='hokuyo'>
    <inertial>
      <mass value="0.1"/>
      <origin xyz="0.0 0 0" rpy="0 0 0"/>
      <inertia
          ixx="1e-6" ixy="0" ixz="0"
          iyy="1e-6" iyz="0"
          izz="1e-6" />
    </inertial>
    <collision name='collision'>
      <origin xyz="0 0 0" rpy=" 0 0 0"/>
      <geometry>
        <box size="0.1 0.1 0.1"/>
      </geometry>
    </collision>
    <visual>
      <origin xyz="0 0 0" rpy="0 0 0"/>
      <geometry>
        <mesh filename="package://slam_project/meshes/hokuyo.dae"/>
        <!-- <box size=".1"/> -->
      </geometry>
      <material name="blue">
            <color rgba="0 0 1.0 1.0" />
      </material>
    </visual>
  </link>

  <joint type="fixed" name="hokuyo_joint">
    <origin xyz="0.15 0 0.1" rpy="0 0 0"/>
    <child link="hokuyo"/>
    <parent link="chassis"/>
  </joint>

  <!-- add a pole and a grapper -->
  <joint name="gripper_extension" type="fixed">
    <parent link="chassis"/>
    <child link="gripper_pole"/>
    <!--<limit effort="1000.0" lower="-0.38" upper="0" velocity="0.5"/>-->
    <!-- <origin rpy="0 -0.7854 0" xyz="0 0 0.1"/> -->
    <origin rpy="0 0 0" xyz="0 0 0.1"/>
  </joint>

  <link name="gripper_pole">
    <visual>
      <geometry>
        <cylinder length="0.14" radius="0.01"/>
      </geometry>
      <origin rpy="0.0 0.0 0.0 " xyz="0 0 0"/>
      <material name="yellow">
            <color rgba="1.0 1.0 0.0 1.0" />
      </material>
    </visual>
    <collision>
      <geometry>
        <cylinder length="0.14" radius="0.01"/>
      </geometry>
      <origin rpy="0.0 0.0 0.0" xyz="0 0 0"/>
    </collision>
    <inertial>
      <mass value="0.05"/>
      <inertia ixx="1.0" ixy="0.0" ixz="0.0" iyy="1.0" iyz="0.0" izz="1.0"/>
    </inertial>
  </link>

  <joint name="left_gripper_joint" type="revolute">
    <!-- <axis xyz="0 0 1"/> -->
    <limit effort="1000.0" lower="0.0" upper="0.548" velocity="0.5"/>
    <origin rpy="0 0 0" xyz="0 0.01 0.1"/>
    <parent link="gripper_pole"/>
    <child link="left_gripper"/>
  </joint>

  <link name="left_gripper">
    <visual>
      <origin rpy="0.0 0 0" xyz="0 0 0"/>
      <geometry>
        <mesh filename="package://slam_project/meshes/l_finger.dae"/>
      </geometry>
    </visual>
    <collision>
      <geometry>
        <mesh filename="package://slam_project/meshes/l_finger.dae"/>
      </geometry>
      <origin rpy="0.0 0 0" xyz="0 0 0"/>
    </collision>
    <inertial>
      <mass value="0.05"/>
      <inertia ixx="1.0" ixy="0.0" ixz="0.0" iyy="1.0" iyz="0.0" izz="1.0"/>
    </inertial>
  </link>

  <joint name="left_tip_joint" type="fixed">
    <parent link="left_gripper"/>
    <child link="left_tip"/>
  </joint>

  <link name="left_tip">
    <visual>
      <origin rpy="0.0 0 0" xyz="0.09137 0.00495 0"/>
      <geometry>
        <mesh filename="package://slam_project/meshes/l_finger_tip.dae"/>
      </geometry>
    </visual>
    <collision>
      <geometry>
        <mesh filename="package://slam_project/meshes/l_finger_tip.dae"/>
      </geometry>
      <origin rpy="0.0 0 0" xyz="0.09137 0.00495 0"/>
    </collision>
    <inertial>
      <mass value="0.05"/>
      <inertia ixx="1.0" ixy="0.0" ixz="0.0" iyy="1.0" iyz="0.0" izz="1.0"/>
    </inertial>
  </link>

  <joint name="right_gripper_joint" type="revolute">
    <!-- <axis xyz="0 0 -1"/> -->
    <limit effort="1000.0" lower="0.0" upper="0.548" velocity="0.5"/>
    <origin rpy="0 0 0" xyz="0 -0.01 0.1"/>
    <parent link="gripper_pole"/>
    <child link="right_gripper"/>
  </joint>

  <link name="right_gripper">
    <visual>
      <origin rpy="-3.1415 0 0" xyz="0 0 0"/>
      <geometry>
        <mesh filename="package://slam_project/meshes/l_finger.dae"/>
      </geometry>
    </visual>
    <collision>
      <geometry>
        <mesh filename="package://slam_project/meshes/l_finger.dae"/>
      </geometry>
      <origin rpy="-3.1415 0 0" xyz="0 0 0"/>
    </collision>
    <inertial>
      <mass value="0.05"/>
      <inertia ixx="1.0" ixy="0.0" ixz="0.0" iyy="1.0" iyz="0.0" izz="1.0"/>
    </inertial>
  </link>

  <joint name="right_tip_joint" type="fixed">
    <parent link="right_gripper"/>
    <child link="right_tip"/>
  </joint>

  <link name="right_tip">
    <visual>
      <origin rpy="-3.1415 0 0" xyz="0.09137 0.00495 0"/>
      <geometry>
        <mesh filename="package://slam_project/meshes/l_finger_tip.dae"/>
      </geometry>
    </visual>
    <collision>
      <geometry>
        <mesh filename="package://slam_project/meshes/l_finger_tip.dae"/>
      </geometry>
      <origin rpy="-3.1415 0 0" xyz="0.09137 0.00495 0"/>
    </collision>
    <inertial>
      <mass value="0.05"/>
      <inertia ixx="1.0" ixy="0.0" ixz="0.0" iyy="1.0" iyz="0.0" izz="1.0"/>
    </inertial>
  </link>

</robot>
